Workbook

Sheet Income Statement
B3: HRDYAM
B5: INR (Crores) | D5: 2026 | E5: 2027 | F5: 2028 | G5: 2029 | H5: 2030 | I5: 2031
B6: ="Income statement"&" - "&B3 -> Income statement - HRDYAM
B7: Revenue | D7: =SUM('Revene & Cost Sheet'!D6:D10) -> 3.55 | E7: =SUM('Revene & Cost Sheet'!E6:E10) -> 5.5 | F7: =SUM('Revene & Cost Sheet'!F6:F10) -> 9 | G7: =SUM('Revene & Cost Sheet'!G6:G10) -> 14 | H7: =SUM('Revene & Cost Sheet'!H6:H10) -> 22 | I7: =SUM('Revene & Cost Sheet'!I6:I10) -> 30
B8: COGS | D8: =SUM('Revene & Cost Sheet'!D16:D21) -> 1.075 | E8: =SUM('Revene & Cost Sheet'!E16:E21) -> 1.6545 | F8: =SUM('Revene & Cost Sheet'!F16:F21) -> 2.7262 | G8: =SUM('Revene & Cost Sheet'!G16:G21) -> 4.20917 | H8: =SUM('Revene & Cost Sheet'!H16:H21) -> 6.647487 | I8: =SUM('Revene & Cost Sheet'!I16:I21) -> 9.0527357
B9: Gross profit | D9: =D7-D8 -> 2.475 | E9: =E7-E8 -> 3.8455 | F9: =F7-F8 -> 6.2738 | G9: =G7-G8 -> 9.79083 | H9: =H7-H8 -> 15.352513 | I9: =I7-I8 -> 20.947264
B10: Employee benefit expenses | D10: =SUM('Revene & Cost Sheet'!D38:D39) -> 0.2175 | E10: =SUM('Revene & Cost Sheet'!E38:E39) -> 0.256125 | F10: =SUM('Revene & Cost Sheet'!F38:F39) -> 0.30283125 | G10: =SUM('Revene & Cost Sheet'!G38:G39) -> 0.35948156 | H10: =SUM('Revene & Cost Sheet'!H38:H39) -> 0.4283887 | I10: =SUM('Revene & Cost Sheet'!I38:I39) -> 0.5124263
B11: Selling expenses | D11: =SUM('Revene & Cost Sheet'!D34:D35) -> 1.26735 | E11: =SUM('Revene & Cost Sheet'!E34:E35) -> 1.7325 | F11: =SUM('Revene & Cost Sheet'!F34:F35) -> 2.457 | G11: =SUM('Revene & Cost Sheet'!G34:G35) -> 3.234 | H11: =SUM('Revene & Cost Sheet'!H34:H35) -> 4.158 | I11: =SUM('Revene & Cost Sheet'!I34:I35) -> 4.725
B12: Administrative expenses | D12: =SUM('Revene & Cost Sheet'!D24:D31) -> 1.671 | E12: =SUM('Revene & Cost Sheet'!E24:E31) -> 1.9825 | F12: =SUM('Revene & Cost Sheet'!F24:F31) -> 2.380375 | G12: =SUM('Revene & Cost Sheet'!G24:G31) -> 2.8761938 | H12: =SUM('Revene & Cost Sheet'!H24:H31) -> 3.5155397 | I12: =SUM('Revene & Cost Sheet'!I24:I31) -> 4.2577519
B13: EBITDA | D13: =D9-SUM(D10,D11,D12) -> -0.68085 | E13: =E9-SUM(E10,E11,E12) -> -0.125625 | F13: =F9-SUM(F10,F11,F12) -> 1.1335937 | G13: =G9-SUM(G10,G11,G12) -> 3.3211547 | H13: =H9-SUM(H10,H11,H12) -> 7.2505846 | I13: =I9-SUM(I10,I11,I12) -> 11.452086
B14: Depreceiation | C14: 0.23 | D14: 0.23 | E14: 0.23 | F14: 0.23 | G14: 0.23 | H14: 0.23 | I14: 0.23
B15: EBIT | D15: =D13-D14 -> -0.91085 | E15: =E13-E14 -> -0.355625 | F15: =F13-F14 -> 0.90359375 | G15: =G13-G14 -> 3.0911547 | H15: =H13-H14 -> 7.0205846 | I15: =I13-I14 -> 11.222086
B16: Interest (Finance cost) | D16: 0 | E16: 0.06 | F16: 0.2 | G16: 0.47 | H16: 0.93 | I16: 1.51
B17: EBT | D17: =D15-D16 -> -0.91085 | E17: =E15-E16 -> -0.415625 | F17: =F15-F16 -> 0.70359375 | G17: =G15-G16 -> 2.6211547 | H17: =H15-H16 -> 6.0905846 | I17: =I15-I16 -> 9.7120861
B18: Tax | C18: 0.346 | D18: =IF(D15<0,0,D15*$C$18) -> 0 | E18: =IF(E15<0,0,E15*$C$18) -> 0 | F18: =IF(F15<0,0,F15*$C$18) -> 0.31264344 | G18: =IF(G15<0,0,G15*$C$18) -> 1.0695395 | H18: =IF(H15<0,0,H15*$C$18) -> 2.4291223 | I18: =IF(I15<0,0,I15*$C$18) -> 3.8828418
B19: PAT | D19: =D17-D18 -> -0.91085 | E19: =E17-E18 -> -0.415625 | F19: =F17-F18 -> 0.39095031 | G19: =G17-G18 -> 1.5516152 | H19: =H17-H18 -> 3.6614623 | I19: =I17-I18 -> 5.8292443
B20: profit after tax

Sheet Balance Sheet
B1: HRDYAM
B3: ="Balance Sheet"&" - "&B1 -> Balance Sheet - HRDYAM
B5: INR (Crores) | D5: 2026 | E5: 2027 | F5: 2028 | G5: 2029 | H5: 2030
B6: EQUITY & LIABILITIES
B7: Shareholders' funds
B8: Share Capital | D8: ='Financial Assumptions'!$D$24 -> 8.55 | E8: ='Financial Assumptions'!$D$24 -> 8.55 | F8: ='Financial Assumptions'!$D$24 -> 8.55 | G8: ='Financial Assumptions'!$D$24 -> 8.55 | H8: ='Financial Assumptions'!$D$24 -> 8.55
B9: Reserves | D9: =Reserves!D8 -> -0.91085 | E9: =Reserves!E8 -> -1.326475 | F9: =Reserves!F8 -> -0.93552469 | G9: =Reserves!G8 -> 0.61609048 | H9: =Reserves!H8 -> 4.2775528
B10: Shareholders' Equity | D10: =D8+D9 -> 7.63915 | E10: =E8+E9 -> 7.223525 | F10: =F8+F9 -> 7.6144753 | G10: =G8+G9 -> 9.1660905 | H10: =H8+H9 -> 12.827553
B12: Non-Current Liabilities
B13: Long term Borrowings | D13: 0 | E13: 0 | F13: 0 | G13: 0 | H13: 0
B15: Current Liabilities
B16: Trade Payables | D16: ='Working Capital'!D15 -> 0.11035288 | E16: ='Working Capital'!E15 -> 0.16413425 | F16: ='Working Capital'!F15 -> 0.25774973 | G16: ='Working Capital'!G15 -> 0.38561055 | H16: ='Working Capital'!H15 -> 0.58271537
B17: Working Capital Loan | D17: ='Working Capital'!D20 -> 0 | E17: ='Working Capital'!E20 -> 0.5 | F17: ='Working Capital'!F20 -> 1.6666667 | G17: ='Working Capital'!G20 -> 3.9166667 | H17: ='Working Capital'!H20 -> 7.75
B18: Promoter Working Capital Margin Infusion | D18: ='Working Capital'!D23 -> 0.0091960731 | E18: ='Working Capital'!E23 -> 0.014842271 | F18: ='Working Capital'!F23 -> 0.024561311 | G18: ='Working Capital'!G23 -> 0.03788763 | H18: ='Working Capital'!H23 -> 0.059107531
B19: Total Current Liabilities | D19: =SUM(D16:D18) -> 0.11954895 | E19: =SUM(E16:E18) -> 0.67897652 | F19: =SUM(F16:F18) -> 1.9489777 | G19: =SUM(G16:G18) -> 4.3401649 | H19: =SUM(H16:H18) -> 8.3918229
B20: TOTAL EQUITY & LIABILITIES | D20: =D10+D13+D19 -> 7.7586989 | E20: =E10+E13+E19 -> 7.9025015 | F20: =F10+F13+F19 -> 9.563453 | G20: =G10+G13+G19 -> 13.506255 | H20: =H10+H13+H19 -> 21.219376
B22: ASSETS
B23: Non Current Assets
B24: Property, plant and equipment
B25: Tangible Assets | D25: ='Fixed Asset Schedule'!D26+'Fixed Asset Schedule'!D27 -> 0.59 | E25: ='Fixed Asset Schedule'!E26+'Fixed Asset Schedule'!E27 -> 0.53 | F25: ='Fixed Asset Schedule'!F26+'Fixed Asset Schedule'!F27 -> 0.59 | G25: ='Fixed Asset Schedule'!G26+'Fixed Asset Schedule'!G27 -> 0.53 | H25: ='Fixed Asset Schedule'!H26+'Fixed Asset Schedule'!H27 -> 0.47
B26: Intangible assets | D26: ='Fixed Asset Schedule'!D28 -> 1.68 | E26: ='Fixed Asset Schedule'!E28 -> 1.51 | F26: ='Fixed Asset Schedule'!F28 -> 1.34 | G26: ='Fixed Asset Schedule'!G28 -> 1.17 | H26: ='Fixed Asset Schedule'!H28 -> 1
D27: =D25+D26 -> 2.27 | E27: =E25+E26 -> 2.04 | F27: =F25+F26 -> 1.93 | G27: =G25+G26 -> 1.7 | H27: =H25+H26 -> 1.47
B29: Current Assets
B30: Inventories | D30: ='Working Capital'!D6 -> #REF! | E30: ='Working Capital'!E6 -> #REF! | F30: ='Working Capital'!F6 -> #REF! | G30: ='Working Capital'!G6 -> #REF! | H30: ='Working Capital'!H6 -> #REF!
B31: Trade Receivables | D31: 0 | E31: 0 | F31: 0 | G31: 0 | H31: 0
B32: Cash and Cash Equivalents | D32: ='Cash Flow'!D29 -> #REF! | E32: ='Cash Flow'!E29 -> #REF! | F32: ='Cash Flow'!F29 -> #REF! | G32: ='Cash Flow'!G29 -> #REF! | H32: ='Cash Flow'!H29 -> #REF!
B33: Total current assets | D33: =SUM(D30:D32) -> #REF! | E33: =SUM(E30:E32) -> #REF! | F33: =SUM(F30:F32) -> #REF! | G33: =SUM(G30:G32) -> #REF! | H33: =SUM(H30:H32) -> #REF!
B34: TOTAL ASSETS | D34: =D25+D26+D33 -> #REF! | E34: =E25+E26+E33 -> #REF! | F34: =F25+F26+F33 -> #REF! | G34: =G25+G26+G33 -> #REF! | H34: =H25+H26+H33 -> #REF!

Sheet Cash Flow
B1: HRDYAM
B3: ="Cash Flow"&" - "&B1 -> Cash Flow - HRDYAM
B5: INR (Crores) | D5: 2026 | E5: 2027 | F5: 2028 | G5: 2029 | H5: 2030
B6: NET INCOME | D6: ='Income Statement'!D19 -> -0.91085 | E6: ='Income Statement'!E19 -> -0.415625 | F6: ='Income Statement'!F19 -> 0.39095031 | G6: ='Income Statement'!G19 -> 1.5516152 | H6: ='Income Statement'!H19 -> 3.6614623
B7: Depreciation | D7: ='Income Statement'!D14 -> 0.23 | E7: ='Income Statement'!E14 -> 0.23 | F7: ='Income Statement'!F14 -> 0.23 | G7: ='Income Statement'!G14 -> 0.23 | H7: ='Income Statement'!H14 -> 0.23
B8: Finance Cost | D8: ='Income Statement'!D16 -> 0 | E8: ='Income Statement'!E16 -> 0.06 | F8: ='Income Statement'!F16 -> 0.2 | G8: ='Income Statement'!G16 -> 0.47 | H8: ='Income Statement'!H16 -> 0.93
B9: Pre-operative expenses written off | D9: 0 | E9: 0 | F9: 0 | G9: 0 | H9: 0
B10: Profit/loss on sale of fixed assets | D10: 0 | E10: 0 | F10: 0 | G10: 0 | H10: 0
B11: Cash from Operations | D11: =SUM(D6:D10) -> -0.68085 | E11: =SUM(E6:E10) -> -0.125625 | F11: =SUM(F6:F10) -> 0.82095031 | G11: =SUM(G6:G10) -> 2.2516152 | H11: =SUM(H6:H10) -> 4.8214623
B12: Inventory | D12: ='Balance Sheet'!D30 -> #REF! | E12: ='Balance Sheet'!E30-'Balance Sheet'!D30 -> #REF! | F12: ='Balance Sheet'!F30-'Balance Sheet'!E30 -> #REF! | G12: ='Balance Sheet'!G30-'Balance Sheet'!F30 -> #REF! | H12: ='Balance Sheet'!H30-'Balance Sheet'!G30 -> #REF!
B13: Payables | D13: ='Balance Sheet'!D16 -> 0.11035288 | E13: ='Balance Sheet'!E16-'Balance Sheet'!D16 -> 0.05378137 | F13: ='Balance Sheet'!F16-'Balance Sheet'!E16 -> 0.093615479 | G13: ='Balance Sheet'!G16-'Balance Sheet'!F16 -> 0.12786083 | H13: ='Balance Sheet'!H16-'Balance Sheet'!G16 -> 0.19710481
B14: Cash from Operating activites | D14: =D11+D12+D13 -> #REF! | E14: =E11+E12+E13 -> #REF! | F14: =F11+F12+F13 -> #REF! | G14: =G11+G12+G13 -> #REF! | H14: =H11+H12+H13 -> #REF!
B16: Preliminary and Pre-operative expenses | D16: 0 | E16: 0 | F16: 0 | G16: 0 | H16: 0
B17: Investment in assets | D17: =-('Financial Assumptions'!$D$43+'Financial Assumptions'!$D$44) -> -2.5 | E17: 0 | F17: 0 | G17: 0 | H17: 0
B18: Cash (used in/from) Investing activities | D18: =D16+D17 -> -2.5 | E18: =E16+E17 -> 0 | F18: =F16+F17 -> 0 | G18: =G16+G17 -> 0 | H18: =H16+H17 -> 0
B20: Proceeds from/Repayment of term loans | D20: 0 | E20: 0 | F20: 0 | G20: 0 | H20: 0
B21: Interest expense on loan & working capital | D21: =-D8 -> 0 | E21: =-E8 -> -0.06 | F21: =-F8 -> -0.2 | G21: =-G8 -> -0.47 | H21: =-H8 -> -0.93
B22: Proceeds from working capital loan | D22: ='Balance Sheet'!D17 -> 0 | E22: ='Balance Sheet'!E17-'Balance Sheet'!D17 -> 0.5 | F22: ='Balance Sheet'!F17-'Balance Sheet'!E17 -> 1.1666667 | G22: ='Balance Sheet'!G17-'Balance Sheet'!F17 -> 2.25 | H22: ='Balance Sheet'!H17-'Balance Sheet'!G17 -> 3.8333333
B23: Proceeds from working capital margin | D23: ='Balance Sheet'!D18 -> 0.0091960731 | E23: ='Balance Sheet'!E18-'Balance Sheet'!D18 -> 0.0056461975 | F23: ='Balance Sheet'!F18-'Balance Sheet'!E18 -> 0.00971904 | G23: ='Balance Sheet'!G18-'Balance Sheet'!F18 -> 0.013326319 | H23: ='Balance Sheet'!H18-'Balance Sheet'!G18 -> 0.021219901
B24: Equity contribution | D24: ='Financial Assumptions'!$D$29 -> 8.55 | E24: 0 | F24: 0 | G24: 0 | H24: 0
B25: Cash from Financing activites | D25: =SUM(D20:D24) -> 8.5591961 | E25: =SUM(E20:E24) -> 0.4456462 | F25: =SUM(F20:F24) -> 0.97638571 | G25: =SUM(G20:G24) -> 1.7933263 | H25: =SUM(H20:H24) -> 2.9245532
B27: Net cash flows during the year | D27: =D14+D18+D25 -> #REF! | E27: =E14+E18+E25 -> #REF! | F27: =F14+F18+F25 -> #REF! | G27: =G14+G18+G25 -> #REF! | H27: =H14+H18+H25 -> #REF!
B28: Opening Balance at the beginning of the year | D28: 0 | E28: =D29 -> #REF! | F28: =E29 -> #REF! | G28: =F29 -> #REF! | H28: =G29 -> #REF!
B29: Closing Balance at the end of the year | D29: =D27+D28 -> #REF! | E29: =E27+E28 -> #REF! | F29: =F27+F28 -> #REF! | G29: =G27+G28 -> #REF! | H29: =H27+H28 -> #REF!

Sheet Reserves
B1: HRDYAM
B3: ="Reserves"&" - "&B1 -> Reserves - HRDYAM
B5: INR (Crores) | D5: 2026 | E5: 2027 | F5: 2028 | G5: 2029 | H5: 2030
B6: Opening balance at the beginning | D6: 0 | E6: =D8 -> -0.91085 | F6: =E8 -> -1.326475 | G6: =F8 -> -0.93552469 | H6: =G8 -> 0.61609048
B7: Profit/Loss for the year | D7: ='Income Statement'!D19 -> -0.91085 | E7: ='Income Statement'!E19 -> -0.415625 | F7: ='Income Statement'!F19 -> 0.39095031 | G7: ='Income Statement'!G19 -> 1.5516152 | H7: ='Income Statement'!H19 -> 3.6614623 | J7: these are the profit after tax
B8: Closing balance at the year end | D8: =SUM(D6:D7) -> -0.91085 | E8: =SUM(E6:E7) -> -1.326475 | F8: =SUM(F6:F7) -> -0.93552469 | G8: =SUM(G6:G7) -> 0.61609048 | H8: =SUM(H6:H7) -> 4.2775528
H9: reserve is the amount that company keep to itself (it is not profit)
D10: reasonable because first 3 years loss m h that is normal in a startup

Sheet Revene & Cost Sheet
B1: HRDYAM
B3: ="Revenue & Cost Sheet"&" - "&B1 -> Revenue & Cost Sheet - HRDYAM
B4: INR (Crores)
B5: REVENUE | D5: 2026 | E5: 2027 | F5: 2028 | G5: 2029 | H5: 2030 | I5: 2031
B6: Astrology | D6: 0.5 | E6: 0.83 | F6: 1.53 | G6: 2.52 | H6: 4.4 | I6: 6.6
B7: Spiritual tourism | D7: 2.8 | E7: 3.95 | F7: 6.12 | G7: 9.1 | H7: 13.64 | I7: 17.4
B8: Merchandise Store | D8: 0 | E8: 0.17 | F8: 0.45 | G8: 0.84 | H8: 1.54 | I8: 2.4
B9: Puja | D9: 0.05 | E9: 0.11 | F9: 0.18 | G9: 0.28 | H9: 0.44 | I9: 0.6
B10: Wellness | D10: 0.2 | E10: 0.44 | F10: 0.72 | G10: 1.26 | H10: 1.98 | I10: 3
D11: =D6+D7+D8+D9+D10 -> 3.55 | E11: =E6+E7+E8+E9+E10 -> 5.5 | F11: =F6+F7+F8+F9+F10 -> 9 | G11: =G6+G7+G8+G9+G10 -> 14 | H11: =H6+H7+H8+H9+H10 -> 22 | I11: =I6+I7+I8+I9+I10 -> 30 | J11: growth mostly 50% and above h early
I12: CAGR 57% k around h | N12: dono bohot zyada h 20% se
B14: EXPENSES
B15: Direct cost
B16: Commission to Astrologers | D16: ='Operating Assumtions'!$D$57*D6 -> 0.15 | E16: ='Operating Assumtions'!$D$57*E6 -> 0.249 | F16: ='Operating Assumtions'!$D$57*F6 -> 0.459 | G16: ='Operating Assumtions'!$D$57*G6 -> 0.756 | H16: ='Operating Assumtions'!$D$57*H6 -> 1.32 | I16: ='Operating Assumtions'!$D$57*I6 -> 1.98
B17: Commission to Retreats | D17: ='Operating Assumtions'!$D$59*D7 -> 0.84 | E17: ='Operating Assumtions'!$D$59*E7 -> 1.185 | F17: ='Operating Assumtions'!$D$59*F7 -> 1.836 | G17: ='Operating Assumtions'!$D$59*G7 -> 2.73 | H17: ='Operating Assumtions'!$D$59*H7 -> 4.092 | I17: ='Operating Assumtions'!$D$59*I7 -> 5.22
B18: Commission to Services | D18: ='Operating Assumtions'!$D$58*D9 -> 0.015 | E18: ='Operating Assumtions'!$D$58*E9 -> 0.033 | F18: ='Operating Assumtions'!$D$58*F9 -> 0.054 | G18: ='Operating Assumtions'!$D$58*G9 -> 0.084 | H18: ='Operating Assumtions'!$D$58*H9 -> 0.132 | I18: ='Operating Assumtions'!$D$58*I9 -> 0.18
B19: Merchandise | D19: ='Operating Assumtions'!$D$90*D8 -> 0 | E19: ='Operating Assumtions'!$D$90*E8 -> 0.1105 | F19: ='Operating Assumtions'!$D$90*F8 -> 0.2925 | G19: ='Operating Assumtions'!$D$90*G8 -> 0.546 | H19: ='Operating Assumtions'!$D$90*H8 -> 1.001 | I19: ='Operating Assumtions'!$D$90*I8 -> 1.56
B20: Legal and Professional Expense | D20: ='Operating Assumtions'!$D$60/10^7 -> 0.01 | E20: =D20*(1+'Operating Assumtions'!$D$80) -> 0.011 | F20: =E20*(1+'Operating Assumtions'!$D$80) -> 0.0121 | G20: =F20*(1+'Operating Assumtions'!$D$80) -> 0.01331 | H20: =G20*(1+'Operating Assumtions'!$D$80) -> 0.014641 | I20: =H20*(1+'Operating Assumtions'!$D$80) -> 0.0161051
B21: IT Cost | D21: ='Operating Assumtions'!$D$61/10^7 -> 0.06 | E21: =D21*(1+'Operating Assumtions'!$D$80) -> 0.066 | F21: =E21*(1+'Operating Assumtions'!$D$80) -> 0.0726 | G21: =F21*(1+'Operating Assumtions'!$D$80) -> 0.07986 | H21: =G21*(1+'Operating Assumtions'!$D$80) -> 0.087846 | I21: =H21*(1+'Operating Assumtions'!$D$80) -> 0.0966306
D22: =D17+D18+D19+D20+D21 -> 0.925 | E22: =E17+E18+E19+E20+E21 -> 1.4055 | F22: =F17+F18+F19+F20+F21 -> 2.2672 | G22: =G17+G18+G19+G20+G21 -> 3.45317 | H22: =H17+H18+H19+H20+H21 -> 5.327487 | I22: =I17+I18+I19+I20+I21 -> 7.0727357
B23: Opex
B24: Salaries & Admin | D24: 0.75 | E24: =D24*1.25 -> 0.9375 | F24: =E24*1.25 -> 1.171875 | G24: =F24*1.25 -> 1.4648438 | H24: =G24*1.25 -> 1.8310547 | I24: =H24*1.25 -> 2.2888184
B25: founder & Management Salaries | D25: 0.7 | E25: =D25*1.1 -> 0.77 | F25: =E25*1.1 -> 0.847 | G25: =F25*1.1 -> 0.9317 | H25: =G25*1.1 -> 1.02487 | I25: =H25*1.1 -> 1.127357
B26: Auditor Fees | D26: 0.01 | E26: =D26*(1+'Operating Assumtions'!$D$80) -> 0.011 | F26: =E26*(1+'Operating Assumtions'!$D$80) -> 0.0121 | G26: =F26*(1+'Operating Assumtions'!$D$80) -> 0.01331 | H26: =G26*(1+'Operating Assumtions'!$D$80) -> 0.014641 | I26: =H26*(1+'Operating Assumtions'!$D$80) -> 0.0161051
B27: Insurance Expense | D27: 0.04 | E27: =D27*(1+'Operating Assumtions'!$D$80) -> 0.044 | F27: =E27*(1+'Operating Assumtions'!$D$80) -> 0.0484 | G27: =F27*(1+'Operating Assumtions'!$D$80) -> 0.05324 | H27: =G27*(1+'Operating Assumtions'!$D$80) -> 0.058564 | I27: =H27*(1+'Operating Assumtions'!$D$80) -> 0.0644204
B28: Power and Fuel | D28: 0.02 | E28: =D28*(1+'Operating Assumtions'!$D$80) -> 0.022 | F28: =E28*(1+'Operating Assumtions'!$D$80) -> 0.0242 | G28: =F28*(1+'Operating Assumtions'!$D$80) -> 0.02662 | H28: =G28*(1+'Operating Assumtions'!$D$80) -> 0.029282 | I28: =H28*(1+'Operating Assumtions'!$D$80) -> 0.0322102
B29: Travel & Conveyances | D29: 0.05 | E29: =D29*(1+'Operating Assumtions'!$D$80) -> 0.055 | F29: =E29*(1+'Operating Assumtions'!$D$80) -> 0.0605 | G29: =F29*(1+'Operating Assumtions'!$D$80) -> 0.06655 | H29: =G29*(1+'Operating Assumtions'!$D$80) -> 0.073205 | I29: =H29*(1+'Operating Assumtions'!$D$80) -> 0.0805255
B30: Office Rent & Expenditures | D30: 0.03 | E30: =D30*(1+'Operating Assumtions'!$D$80) -> 0.033 | F30: =E30*(1+'Operating Assumtions'!$D$80) -> 0.0363 | G30: =F30*(1+'Operating Assumtions'!$D$80) -> 0.03993 | H30: =G30*(1+'Operating Assumtions'!$D$80) -> 0.043923 | I30: =H30*(1+'Operating Assumtions'!$D$80) -> 0.0483153
B31: Payment Gateway Charges | D31: ='Operating Assumtions'!$D$70*SUM(D6:D10) -> 0.071 | E31: ='Operating Assumtions'!$D$70*SUM(E6:E10) -> 0.11 | F31: ='Operating Assumtions'!$D$70*SUM(F6:F10) -> 0.18 | G31: ='Operating Assumtions'!$D$70*SUM(G6:G10) -> 0.28 | H31: ='Operating Assumtions'!$D$70*SUM(H6:H10) -> 0.44 | I31: ='Operating Assumtions'!$D$70*SUM(I6:I10) -> 0.6
D32: =D24+D25+D26+D27+D28+D29+D30+D31 -> 1.671 | E32: =E24+E25+E26+E27+E28+E29+E30+E31 -> 1.9825 | F32: =F24+F25+F26+F27+F28+F29+F30+F31 -> 2.380375 | G32: =G24+G25+G26+G27+G28+G29+G30+G31 -> 2.8761938 | H32: =H24+H25+H26+H27+H28+H29+H30+H31 -> 3.5155397 | I32: =I24+I25+I26+I27+I28+I29+I30+I31 -> 4.2577519
B33: Marketing
B34: Business Promotion/Digital Mark | D34: ='Operating Assumtions'!D91*SUM(D6:D10) -> 1.207 | E34: ='Operating Assumtions'!E91*SUM(E6:E10) -> 1.65 | F34: ='Operating Assumtions'!F91*SUM(F6:F10) -> 2.34 | G34: ='Operating Assumtions'!G91*SUM(G6:G10) -> 3.08 | H34: ='Operating Assumtions'!H91*SUM(H6:H10) -> 3.96 | I34: ='Operating Assumtions'!I91*SUM(I6:I10) -> 4.5
B35: Content Development/Creation | D35: ='Operating Assumtions'!$D$75*D34 -> 0.06035 | E35: ='Operating Assumtions'!$D$75*E34 -> 0.0825 | F35: ='Operating Assumtions'!$D$75*F34 -> 0.117 | G35: ='Operating Assumtions'!$D$75*G34 -> 0.154 | H35: ='Operating Assumtions'!$D$75*H34 -> 0.198 | I35: ='Operating Assumtions'!$D$75*I34 -> 0.225
D36: =D34+D35 -> 1.26735 | E36: =E34+E35 -> 1.7325 | F36: =F34+F35 -> 2.457 | G36: =G34+G35 -> 3.234 | H36: =H34+H35 -> 4.158 | I36: =I34+I35 -> 4.725
B37: HR
B38: Employee Benefits (EPF, Gratuity, etc.) | D38: =0.12*(D24+D25) -> 0.174 | E38: =0.12*(E24+E25) -> 0.2049 | F38: =0.12*(F24+F25) -> 0.242265 | G38: =0.12*(G24+G25) -> 0.28758525 | H38: =0.12*(H24+H25) -> 0.34271096 | I38: =0.12*(I24+I25) -> 0.40994104
B39: HR (Recruitment Expenses) | D39: =0.03*(D24+D25) -> 0.0435 | E39: =0.03*(E24+E25) -> 0.051225 | F39: =0.03*(F24+F25) -> 0.06056625 | G39: =0.03*(G24+G25) -> 0.071896313 | H39: =0.03*(H24+H25) -> 0.085677741 | I39: =0.03*(I24+I25) -> 0.10248526
D40: =D38+D39 -> 0.2175 | E40: =E38+E39 -> 0.256125 | F40: =F38+F39 -> 0.30283125 | G40: =G38+G39 -> 0.35948156 | H40: =H38+H39 -> 0.4283887 | I40: =I38+I39 -> 0.5124263
B43: total revenue | D43: 30
B44: total expense | D44: =I22+I32+I36+I40 -> 16.567914 | E44: monthly expense is around 26 lakh
...

Sheet Fixed Asset Schedule
B1: HRDYAM
B3: ="Fixed Asset Schedule"&" - "&B1 -> Fixed Asset Schedule - HRDYAM
B5: INR (Crores) | D5: 2026 | E5: 2027 | F5: 2028 | G5: 2029 | H5: 2030
B6: Gross Block
B7: Furniture and fixtures | D7: ='Financial Assumptions'!$D$43 -> 0.65 | E7: =D7 -> 0.65 | F7: =E7 -> 0.65 | G7: =F7 -> 0.65 | H7: =G7 -> 0.65
B8: Laptops/Computers | D8: 0 | E8: =D8 -> 0 | F8: 0.12 | G8: =F8 -> 0.12 | H8: =G8 -> 0.12
B9: IT infrastructure | C9: IT m software already 1.8 | D9: ='Financial Assumptions'!$D$44 -> 1.85 | E9: =D9 -> 1.85 | F9: =E9 -> 1.85 | G9: =F9 -> 1.85 | H9: =G9 -> 1.85
B10: Total | D10: =SUM(D7:D9) -> 2.5 | E10: =SUM(E7:E9) -> 2.5 | F10: =SUM(F7:F9) -> 2.62 | G10: =SUM(G7:G9) -> 2.62 | H10: =SUM(H7:H9) -> 2.62
B13: Depreciation (on straight line depreciation basis) | C13: same depreciation amount every year
B14: Furniture and fixtures | D14: 0.06 | E14: 0.06 | F14: 0.06 | G14: 0.06 | H14: 0.06
B15: for laptops | D15: 0 | E15: 0 | F15: 0 | G15: 0 | H15: 0 | I15: Depreciation amount have to check
B16: IT infrastructure | D16: 0.17 | E16: 0.17 | F16: 0.17 | G16: 0.17 | H16: 0.17
B17: Total | D17: =SUM(D14:D16) -> 0.23 | E17: =SUM(E14:E16) -> 0.23 | F17: =SUM(F14:F16) -> 0.23 | G17: =SUM(G14:G16) -> 0.23 | H17: =SUM(H14:H16) -> 0.23
B19: Accumulated depreciation
B20: Furniture and fixtures | D20: =D14 -> 0.06 | E20: =D20+D14 -> 0.12 | F20: =E20+E14 -> 0.18 | G20: =F20+F14 -> 0.24 | H20: =G20+G14 -> 0.3
B21: for laptops | D21: =D15 -> 0 | E21: =D21+D15 -> 0 | F21: =E21+E15 -> 0 | G21: =F21+F15 -> 0 | H21: =G21+G15 -> 0
B22: IT infrastructure | D22: =D16 -> 0.17 | E22: =D22+D16 -> 0.34 | F22: =E22+E16 -> 0.51 | G22: =F22+F16 -> 0.68 | H22: =G22+G16 -> 0.85
B23: Total | D23: =SUM(D20:D22) -> 0.23 | E23: =SUM(E20:E22) -> 0.46 | F23: =SUM(F20:F22) -> 0.69 | G23: =SUM(G20:G22) -> 0.92 | H23: =SUM(H20:H22) -> 1.15
B25: Net Block
B26: Furniture and fixtures | D26: =D7-D20 -> 0.59 | E26: =E7-E20 -> 0.53 | F26: =F7-F20 -> 0.47 | G26: =G7-G20 -> 0.41 | H26: =H7-H20 -> 0.35
B27: for laptops | D27: =D8-D21 -> 0 | E27: =E8-E21 -> 0 | F27: =F8-F21 -> 0.12 | G27: =G8-G21 -> 0.12 | H27: =H8-H21 -> 0.12
B28: IT infrastructure | D28: =D9-D22 -> 1.68 | E28: =E9-E22 -> 1.51 | F28: =F9-F22 -> 1.34 | G28: =G9-G22 -> 1.17 | H28: =H9-H22 -> 1
B29: Total | D29: =SUM(D26:D28) -> 2.27 | E29: =SUM(E26:E28) -> 2.04 | F29: =SUM(F26:F28) -> 1.93 | G29: =SUM(G26:G28) -> 1.7 | H29: =SUM(H26:H28) -> 1.47

Sheet Financial Assumptions
B1: HRDYAM
B3: ="Financial Assumptions"&" - "&B1 -> Financial Assumptions - HRDYAM
B4: INR (Crores)
B5: TOTAL INVESTMENT REQUIRED | D5: =D21 -> 8.55
B6: Capex
B7: Office furniture & fixtures | D7: 0.15
B8: Opex
B9: Tech development and app | D9: 1.8
B10: Software/subscriptions | D10: 0.1
B11: Contingency | D11: 0.2
B12: Rental/lease | D12: 0.1
B13: Preliminary & Pre-operative expenses | D13: 0.3
B14: WC
B15: Working capital requirement | D15: 1.2
B16: Salaries for the year | D16: 1.6
B17: Marketing expenses | D17: 2.2
B18: Travel, Recruitment, Merchandise | D18: 0.3
B19: Fees (Legal, Auditor, Payment gatway) | D19: 0.6
B20: Misc | D20: 0
B21: Cumulative funds deployed | D21: =D7+D9+D10+D11+D12+D13+D15+D16+D17+D18+D19+D20 -> 8.55
B23: Financing structure
B24: Equity | D24: =D21 -> 8.55
B25: LT loan | D25: 0
B26: Seed funding | D26: =D21 -> 8.55
B27: Total funding | D27: =D24+D25 -> 8.55
B29: Total Equity | D29: =D24 -> 8.55
B30: Y0 funding | D30: =0.5*D29 -> 4.275
B31: Y1 funding | D31: =D29-D30 -> 4.275
B33: Tangible & intangible assets
B34: Office furniture | D34: 0.15
B35: Computers/laptops | D35: 0.3
B36: Softwares | D36: 1.8
B37: Vehicles | D37: 0
B38: Inverter | D38: 0.02
B39: Generator | D39: 0.05
B40: Airconditioners | D40: 0.03
B41: Trademark | D41: 0.05
B42: Others (mobile for testing, printer, intercom, time office etc.) | D42: 0.1
B43: Total Tangible Assets | D43: =D34+D35+D37+D38+D39+D40+D42 -> 0.65
B44: Total Intangible Assets | D44: =D36+D41 -> 1.85
...

Sheet Working Capital
B1: HRDYAM
B3: ="Working Capital"&" - "&B1 -> Working Capital - HRDYAM
B5: INR (Crores) | D5: 2026 | E5: 2027 | F5: 2028 | G5: 2029 | H5: 2030
B6: Inventory | D6: ='Operating Assumtions'!#REF!/365*'Revene & Cost Sheet'!D8 -> #REF! | E6: ='Operating Assumtions'!#REF!/365*'Revene & Cost Sheet'!E8 -> #REF! | F6: ='Operating Assumtions'!#REF!/365*'Revene & Cost Sheet'!F8 -> #REF! | G6: ='Operating Assumtions'!#REF!/365*'Revene & Cost Sheet'!G8 -> #REF! | H6: ='Operating Assumtions'!#REF!/365*'Revene & Cost Sheet'!H8 -> #REF!
B7: Merchandise | D7: 0 | E7: 0.013973 | F7: 0.036986 | G7: 0.069041 | H7: 0.126575
B8: Current Assets | D8: 0 | E8: 0.013973 | F8: 0.036986 | G8: 0.069041 | H8: 0.126575
B10: Payables
B11: Astrology | D11: =20/365*'Income Statement'!D8*0.4 -> 0.023561644 | E11: =20/365*'Income Statement'!E8*0.4 -> 0.036263014 | F11: =20/365*'Income Statement'!F8*0.4 -> 0.059752329 | G11: =20/365*'Income Statement'!G8*0.4 -> 0.092255781 | H11: =20/365*'Income Statement'!H8*0.4 -> 0.14569835
B12: Retreats | D12: =20/365*'Income Statement'!D9*0.4 -> 0.054246575 | E12: =20/365*'Income Statement'!E9*0.4 -> 0.084284932 | F12: =20/365*'Income Statement'!F9*0.4 -> 0.13750795 | G12: =20/365*'Income Statement'!G9*0.4 -> 0.21459353 | H12: =20/365*'Income Statement'!H9*0.4 -> 0.33649344
B13: Services | D13: =20/365*'Income Statement'!D10*0.4 -> 0.0047671233 | E13: =20/365*'Income Statement'!E10*0.4 -> 0.0056136986 | F13: =20/365*'Income Statement'!F10*0.4 -> 0.0066373973 | G13: =20/365*'Income Statement'!G10*0.4 -> 0.0078790479 | H13: =20/365*'Income Statement'!H10*0.4 -> 0.0093893414
B14: Merchandise | D14: =20/365*'Income Statement'!D11*0.4 -> 0.027777534 | E14: =20/365*'Income Statement'!E11*0.4 -> 0.037972603 | F14: =20/365*'Income Statement'!F11*0.4 -> 0.053852055 | G14: =20/365*'Income Statement'!G11*0.4 -> 0.070882192 | H14: =20/365*'Income Statement'!H11*0.4 -> 0.091134247
B15: Net Payables | D15: =SUM(D11:D14) -> 0.11035288 | E15: =SUM(E11:E14) -> 0.16413425 | F15: =SUM(F11:F14) -> 0.25774973 | G15: =SUM(G11:G14) -> 0.38561055 | H15: =SUM(H11:H14) -> 0.58271537
B17: Net Working Capital | D17: =D8+D15 -> 0.11035288 | E17: =E8+E15 -> 0.17810725 | F17: =F8+F15 -> 0.29473573 | G17: =G8+G15 -> 0.45465155 | H17: =H8+H15 -> 0.70929037
B19: Working Capital Margin | D19: =0.25*D17 -> 0.027588219 | E19: =0.25*E17 -> 0.044526812 | F19: =0.25*F17 -> 0.073683932 | G19: =0.25*G17 -> 0.11366289 | H19: =0.25*H17 -> 0.17732259
B20: Working Capital Loan | D20: ='Income Statement'!D16/0.12 -> 0 | E20: ='Income Statement'!E16/0.12 -> 0.5 | F20: ='Income Statement'!F16/0.12 -> 1.6666667 | G20: ='Income Statement'!G16/0.12 -> 3.9166667 | H20: ='Income Statement'!H16/0.12 -> 7.75
B21: Interest on working capital loan | D21: =0.12*D20 -> 0 | E21: =0.12*E20 -> 0.06 | F21: =0.12*F20 -> 0.2 | G21: =0.12*G20 -> 0.47 | H21: =0.12*H20 -> 0.93
B23: Working Capital Margin Infusion | D23: =D19*(0.25/0.75) -> 0.0091960731 | E23: =E19*(0.25/0.75) -> 0.014842271 | F23: =F19*(0.25/0.75) -> 0.024561311 | G23: =G19*(0.25/0.75) -> 0.03788763 | H23: =H19*(0.25/0.75) -> 0.059107531

Sheet Operating Assumtions
B1: HRDYAM
B3: ="Operating Assumptions"&" - "&B1 -> Operating Assumptions - HRDYAM
B4: INR (Crores)
C5: M1 | D5: M2 | E5: M3 | F5: M4 | G5: M5 | H5: M6 | I5: M7 | J5: M8 | K5: M9 | L5: M10 | M5: M11 | N5: M12 | O5: Average
B6: 2026 | G6: 36 | H6: 38 | I6: 40 | J6: 42 | K6: 44 | L6: 46 | M6: 48 | N6: 50 | O6: =AVERAGE(C6:N6) -> 43
B7: 2027 | C7: 52 | D7: 54 | E7: 56 | F7: 58 | G7: 60 | H7: 62 | I7: 64 | J7: 66 | K7: 68 | L7: 70 | M7: 72 | N7: 74 | O7: =AVERAGE(C7:N7) -> 63
B8: 2028 | C8: 276 | D8: 478 | E8: 680 | F8: 882 | G8: 1084 | H8: 1286 | I8: 1488 | J8: 1690 | K8: 1892 | L8: 2094 | M8: 2296 | N8: 2498 | O8: =AVERAGE(C8:N8) -> 1387
B9: 2029 | C9: 26100 | D9: 28120 | E9: 30140 | F9: 32160 | G9: 34180 | H9: 36200 | I9: 38220 | J9: 40240 | K9: 42260 | L9: 44280 | M9: 46300 | N9: 48320 | O9: =AVERAGE(C9:N9) -> 37210
B10: 2030 | C10: 50340 | D10: 52360 | E10: 54380 | F10: 56400 | G10: 58420 | H10: 60440 | I10: 62460 | J10: 64480 | K10: 66500 | L10: 68520 | M10: 70540 | N10: 72560 | O10: =AVERAGE(C10:N10) -> 61450
C12: Min/day | D12: Rs./min | E12: Days/mon | H12: tables are not important for pre-seed or seed funding
B13: 2026 | C13: 200 | D13: 25 | E13: 22 | H13: if keeping it then amount should change in peak seasons instead of 2x monthly growth
B14: 2027 | C14: 220 | D14: 30 | E14: 23
B15: 2028 | C15: 230 | D15: 35 | E15: 24
B16: 2029 | C16: 240 | D16: 40 | E16: 25
B17: 2030 | C17: 250 | D17: 45 | E17: 25
B20: Growth Rate | D20: 0.5
D22: Amount
B23: Online consultation | D23: 0.5
B24: Live sessions | D24: 0
B25: Micro Services (FreeAd) | D25: 0
B26: Retreats | D26: 1.5
B27: Astro Vaastu (Ind.) | D27: 0
B28: Services (Rituals) | D28: 0.05
B29: Paid Webinars | D29: 0
B30: Subscription | D30: 0.2
B31: Coporate | D31: 0.3
B32: AstroTourism | D32: 1
B33: Merchandise | D33: 0
B34: Offline fee | D34: 0
B35: Corporate Vaastu | D35: 0
B37: Retreat/Yoga
B38: No. of batches/Year | D38: 20
B39: Person/ Batch | D39: 12
B40: Commission sharing'Growth rate | D40: 0.4
B41: Paid webinar | D41: 99
B42: No. of webinars | D42: 24
B43: No. of person/batch | D43: 200
B45: Payables
B46: Bracelets
B47: Yantra
...
